{"modules": [{"testcases": [{"error": {"message": "ImportError: No module named path_from_points", "traceback": [{"linenr": 329, "function": "run", "line": "testMethod()", "filename": "/usr/lib/python2.7/unittest/case.py"}, {"linenr": 418, "function": "loadTestsFromName", "line": "addr.filename, addr.module)", "filename": "/usr/lib/python2.7/dist-packages/nose/loader.py"}, {"linenr": 47, "function": "importFromPath", "line": "return self.importFromDir(dir_path, fqname)", "filename": "/usr/lib/python2.7/dist-packages/nose/importer.py"}, {"linenr": 94, "function": "importFromDir", "line": "mod = load_module(part_fqname, fh, filename, desc)", "filename": "/usr/lib/python2.7/dist-packages/nose/importer.py"}, {"linenr": 6, "function": "<module>", "line": "from path_from_points import addio", "filename": "/home/sam/fast_ws/src/guidebot/guidebot_navigation/test/path_from_points_test.py"}]}, "result": "error", "name": "runTest"}], "nr_error": 1, "nr_success": 0, "name": "nose.failure.Failure", "nr_failed": 0}], "metadata": {"command": "/usr/bin/nosetests --with-json-extended", "cwd": "/home/sam/fast_ws/src/guidebot/guidebot_navigation/test", "time": 1519594327.482298}}